[2023-10-06 10:57:16,905] {taskinstance.py:1032} INFO - Dependencies all met for <TaskInstance: dag_fligoo_etl.run_etl_task manual__2023-10-06T10:57:11.923035+00:00 [queued]>
[2023-10-06 10:57:16,931] {taskinstance.py:1032} INFO - Dependencies all met for <TaskInstance: dag_fligoo_etl.run_etl_task manual__2023-10-06T10:57:11.923035+00:00 [queued]>
[2023-10-06 10:57:16,931] {taskinstance.py:1238} INFO - 
--------------------------------------------------------------------------------
[2023-10-06 10:57:16,932] {taskinstance.py:1239} INFO - Starting attempt 1 of 1
[2023-10-06 10:57:16,932] {taskinstance.py:1240} INFO - 
--------------------------------------------------------------------------------
[2023-10-06 10:57:16,958] {taskinstance.py:1259} INFO - Executing <Task(PythonOperator): run_etl_task> on 2023-10-06 10:57:11.923035+00:00
[2023-10-06 10:57:16,964] {standard_task_runner.py:52} INFO - Started process 2297 to run task
[2023-10-06 10:57:16,970] {standard_task_runner.py:76} INFO - Running: ['***', 'tasks', 'run', 'dag_fligoo_etl', 'run_etl_task', 'manual__2023-10-06T10:57:11.923035+00:00', '--job-id', '2', '--raw', '--subdir', 'DAGS_FOLDER/dag_fligoo_etl.py', '--cfg-path', '/tmp/tmpmzae4_9u', '--error-file', '/tmp/tmpdtmtr50w']
[2023-10-06 10:57:16,972] {standard_task_runner.py:77} INFO - Job 2: Subtask run_etl_task
[2023-10-06 10:57:17,051] {logging_mixin.py:109} INFO - Running <TaskInstance: dag_fligoo_etl.run_etl_task manual__2023-10-06T10:57:11.923035+00:00 [running]> on host f0647ca95f12
[2023-10-06 10:57:17,141] {taskinstance.py:1426} INFO - Exporting the following env vars:
AIRFLOW_CTX_DAG_OWNER=Damian
AIRFLOW_CTX_DAG_ID=dag_fligoo_etl
AIRFLOW_CTX_TASK_ID=run_etl_task
AIRFLOW_CTX_EXECUTION_DATE=2023-10-06T10:57:11.923035+00:00
AIRFLOW_CTX_DAG_RUN_ID=manual__2023-10-06T10:57:11.923035+00:00
[2023-10-06 10:57:17,143] {logging_mixin.py:109} INFO - >>> Running 'etl' function. Logged at 2023-10-06 10:57:17.143072+00:00
[2023-10-06 10:57:17,143] {logging_mixin.py:109} INFO - >>> Running 'connect_db' function. Logged at 2023-10-06 10:57:17.143703+00:00
[2023-10-06 10:57:17,144] {logging_mixin.py:109} INFO - Connecting to DB
[2023-10-06 10:57:17,156] {logging_mixin.py:109} INFO - >>> Function: 'connect_db' executed. Logged at 2023-10-06 10:57:17.143703+00:00
[2023-10-06 10:57:17,157] {logging_mixin.py:109} INFO - >>> Running 'extract' function. Logged at 2023-10-06 10:57:17.157398+00:00
[2023-10-06 10:57:17,157] {logging_mixin.py:109} INFO - Reading dataset from http://api.aviationstack.com/v1/flights
[2023-10-06 10:57:17,158] {taskinstance.py:1700} ERROR - Task failed with exception
Traceback (most recent call last):
  File "/home/airflow/.local/lib/python3.7/site-packages/airflow/models/taskinstance.py", line 1329, in _run_raw_task
    self._execute_task_with_callbacks(context)
  File "/home/airflow/.local/lib/python3.7/site-packages/airflow/models/taskinstance.py", line 1455, in _execute_task_with_callbacks
    result = self._execute_task(context, self.task)
  File "/home/airflow/.local/lib/python3.7/site-packages/airflow/models/taskinstance.py", line 1511, in _execute_task
    result = execute_callable(context=context)
  File "/home/airflow/.local/lib/python3.7/site-packages/airflow/operators/python.py", line 174, in execute
    return_value = self.execute_callable()
  File "/home/airflow/.local/lib/python3.7/site-packages/airflow/operators/python.py", line 185, in execute_callable
    return self.python_callable(*self.op_args, **self.op_kwargs)
  File "/opt/airflow/dags/dag_fligoo_etl.py", line 44, in wrapper
    to_execute = func(*args, **kwargs)
  File "/opt/airflow/dags/dag_fligoo_etl.py", line 136, in etl
    raw_df = extract(DATASET_URL)
  File "/opt/airflow/dags/dag_fligoo_etl.py", line 44, in wrapper
    to_execute = func(*args, **kwargs)
  File "/opt/airflow/dags/dag_fligoo_etl.py", line 80, in extract
    'access_key': CONFIG["API_ACCESS_KEY"],
  File "/usr/local/lib/python3.7/os.py", line 681, in __getitem__
    raise KeyError(key) from None
KeyError: 'API_ACCESS_KEY'
[2023-10-06 10:57:17,186] {taskinstance.py:1277} INFO - Marking task as FAILED. dag_id=dag_fligoo_etl, task_id=run_etl_task, execution_date=20231006T105711, start_date=20231006T105716, end_date=20231006T105717
[2023-10-06 10:57:17,218] {standard_task_runner.py:92} ERROR - Failed to execute job 2 for task run_etl_task
Traceback (most recent call last):
  File "/home/airflow/.local/lib/python3.7/site-packages/airflow/task/task_runner/standard_task_runner.py", line 85, in _start_by_fork
    args.func(args, dag=self.dag)
  File "/home/airflow/.local/lib/python3.7/site-packages/airflow/cli/cli_parser.py", line 48, in command
    return func(*args, **kwargs)
  File "/home/airflow/.local/lib/python3.7/site-packages/airflow/utils/cli.py", line 92, in wrapper
    return f(*args, **kwargs)
  File "/home/airflow/.local/lib/python3.7/site-packages/airflow/cli/commands/task_command.py", line 298, in task_run
    _run_task_by_selected_method(args, dag, ti)
  File "/home/airflow/.local/lib/python3.7/site-packages/airflow/cli/commands/task_command.py", line 107, in _run_task_by_selected_method
    _run_raw_task(args, ti)
  File "/home/airflow/.local/lib/python3.7/site-packages/airflow/cli/commands/task_command.py", line 184, in _run_raw_task
    error_file=args.error_file,
  File "/home/airflow/.local/lib/python3.7/site-packages/airflow/utils/session.py", line 70, in wrapper
    return func(*args, session=session, **kwargs)
  File "/home/airflow/.local/lib/python3.7/site-packages/airflow/models/taskinstance.py", line 1329, in _run_raw_task
    self._execute_task_with_callbacks(context)
  File "/home/airflow/.local/lib/python3.7/site-packages/airflow/models/taskinstance.py", line 1455, in _execute_task_with_callbacks
    result = self._execute_task(context, self.task)
  File "/home/airflow/.local/lib/python3.7/site-packages/airflow/models/taskinstance.py", line 1511, in _execute_task
    result = execute_callable(context=context)
  File "/home/airflow/.local/lib/python3.7/site-packages/airflow/operators/python.py", line 174, in execute
    return_value = self.execute_callable()
  File "/home/airflow/.local/lib/python3.7/site-packages/airflow/operators/python.py", line 185, in execute_callable
    return self.python_callable(*self.op_args, **self.op_kwargs)
  File "/opt/airflow/dags/dag_fligoo_etl.py", line 44, in wrapper
    to_execute = func(*args, **kwargs)
  File "/opt/airflow/dags/dag_fligoo_etl.py", line 136, in etl
    raw_df = extract(DATASET_URL)
  File "/opt/airflow/dags/dag_fligoo_etl.py", line 44, in wrapper
    to_execute = func(*args, **kwargs)
  File "/opt/airflow/dags/dag_fligoo_etl.py", line 80, in extract
    'access_key': CONFIG["API_ACCESS_KEY"],
  File "/usr/local/lib/python3.7/os.py", line 681, in __getitem__
    raise KeyError(key) from None
KeyError: 'API_ACCESS_KEY'
[2023-10-06 10:57:17,230] {local_task_job.py:154} INFO - Task exited with return code 1
[2023-10-06 10:57:17,310] {local_task_job.py:264} INFO - 0 downstream tasks scheduled from follow-on schedule check
