[2023-10-06 11:02:18,824] {taskinstance.py:1032} INFO - Dependencies all met for <TaskInstance: dag_fligoo_etl.run_etl_task manual__2023-10-06T11:02:16.971384+00:00 [queued]>
[2023-10-06 11:02:18,852] {taskinstance.py:1032} INFO - Dependencies all met for <TaskInstance: dag_fligoo_etl.run_etl_task manual__2023-10-06T11:02:16.971384+00:00 [queued]>
[2023-10-06 11:02:18,853] {taskinstance.py:1238} INFO - 
--------------------------------------------------------------------------------
[2023-10-06 11:02:18,853] {taskinstance.py:1239} INFO - Starting attempt 1 of 1
[2023-10-06 11:02:18,854] {taskinstance.py:1240} INFO - 
--------------------------------------------------------------------------------
[2023-10-06 11:02:18,883] {taskinstance.py:1259} INFO - Executing <Task(PythonOperator): run_etl_task> on 2023-10-06 11:02:16.971384+00:00
[2023-10-06 11:02:18,890] {standard_task_runner.py:52} INFO - Started process 2567 to run task
[2023-10-06 11:02:18,897] {standard_task_runner.py:76} INFO - Running: ['***', 'tasks', 'run', 'dag_fligoo_etl', 'run_etl_task', 'manual__2023-10-06T11:02:16.971384+00:00', '--job-id', '5', '--raw', '--subdir', 'DAGS_FOLDER/dag_fligoo_etl.py', '--cfg-path', '/tmp/tmprrkj24ig', '--error-file', '/tmp/tmpc4cj171a']
[2023-10-06 11:02:18,899] {standard_task_runner.py:77} INFO - Job 5: Subtask run_etl_task
[2023-10-06 11:02:19,004] {logging_mixin.py:109} INFO - Running <TaskInstance: dag_fligoo_etl.run_etl_task manual__2023-10-06T11:02:16.971384+00:00 [running]> on host f0647ca95f12
[2023-10-06 11:02:19,111] {taskinstance.py:1426} INFO - Exporting the following env vars:
AIRFLOW_CTX_DAG_OWNER=Damian
AIRFLOW_CTX_DAG_ID=dag_fligoo_etl
AIRFLOW_CTX_TASK_ID=run_etl_task
AIRFLOW_CTX_EXECUTION_DATE=2023-10-06T11:02:16.971384+00:00
AIRFLOW_CTX_DAG_RUN_ID=manual__2023-10-06T11:02:16.971384+00:00
[2023-10-06 11:02:19,113] {logging_mixin.py:109} INFO - >>> Running 'etl' function. Logged at 2023-10-06 11:02:19.113338+00:00
[2023-10-06 11:02:19,114] {logging_mixin.py:109} INFO - >>> Running 'connect_db' function. Logged at 2023-10-06 11:02:19.114007+00:00
[2023-10-06 11:02:19,114] {logging_mixin.py:109} INFO - Connecting to DB
[2023-10-06 11:02:19,131] {logging_mixin.py:109} INFO - >>> Function: 'connect_db' executed. Logged at 2023-10-06 11:02:19.114007+00:00
[2023-10-06 11:02:19,132] {logging_mixin.py:109} INFO - >>> Running 'extract' function. Logged at 2023-10-06 11:02:19.132198+00:00
[2023-10-06 11:02:19,132] {logging_mixin.py:109} INFO - Reading dataset from http://api.aviationstack.com/v1/flights
[2023-10-06 11:02:19,526] {logging_mixin.py:109} INFO - >>> Function: 'extract' executed. Logged at 2023-10-06 11:02:19.132198+00:00
[2023-10-06 11:02:19,527] {logging_mixin.py:109} INFO - >>> Running 'transform' function. Logged at 2023-10-06 11:02:19.527471+00:00
[2023-10-06 11:02:19,528] {logging_mixin.py:109} INFO - Transforming data
[2023-10-06 11:02:19,541] {taskinstance.py:1700} ERROR - Task failed with exception
Traceback (most recent call last):
  File "/home/airflow/.local/lib/python3.7/site-packages/airflow/models/taskinstance.py", line 1329, in _run_raw_task
    self._execute_task_with_callbacks(context)
  File "/home/airflow/.local/lib/python3.7/site-packages/airflow/models/taskinstance.py", line 1455, in _execute_task_with_callbacks
    result = self._execute_task(context, self.task)
  File "/home/airflow/.local/lib/python3.7/site-packages/airflow/models/taskinstance.py", line 1511, in _execute_task
    result = execute_callable(context=context)
  File "/home/airflow/.local/lib/python3.7/site-packages/airflow/operators/python.py", line 174, in execute
    return_value = self.execute_callable()
  File "/home/airflow/.local/lib/python3.7/site-packages/airflow/operators/python.py", line 185, in execute_callable
    return self.python_callable(*self.op_args, **self.op_kwargs)
  File "/opt/airflow/dags/dag_fligoo_etl.py", line 44, in wrapper
    to_execute = func(*args, **kwargs)
  File "/opt/airflow/dags/dag_fligoo_etl.py", line 140, in etl
    raw_df = transform(raw_df)
  File "/opt/airflow/dags/dag_fligoo_etl.py", line 44, in wrapper
    to_execute = func(*args, **kwargs)
  File "/opt/airflow/dags/dag_fligoo_etl.py", line 100, in transform
    'arrival.airport', 'arrival.timezone', 'arrival.terminal', 'airline.name', 'flight.number']]
  File "/home/airflow/.local/lib/python3.7/site-packages/pandas/core/frame.py", line 3464, in __getitem__
    indexer = self.loc._get_listlike_indexer(key, axis=1)[1]
  File "/home/airflow/.local/lib/python3.7/site-packages/pandas/core/indexing.py", line 1314, in _get_listlike_indexer
    self._validate_read_indexer(keyarr, indexer, axis)
  File "/home/airflow/.local/lib/python3.7/site-packages/pandas/core/indexing.py", line 1374, in _validate_read_indexer
    raise KeyError(f"None of [{key}] are in the [{axis_name}]")
KeyError: "None of [Index(['flight_date', 'flight_status', 'departure.airport',\n       'departure.timezone', 'arrival.airport', 'arrival.timezone',\n       'arrival.terminal', 'airline.name', 'flight.number'],\n      dtype='object')] are in the [columns]"
[2023-10-06 11:02:19,576] {taskinstance.py:1277} INFO - Marking task as FAILED. dag_id=dag_fligoo_etl, task_id=run_etl_task, execution_date=20231006T110216, start_date=20231006T110218, end_date=20231006T110219
[2023-10-06 11:02:19,610] {standard_task_runner.py:92} ERROR - Failed to execute job 5 for task run_etl_task
Traceback (most recent call last):
  File "/home/airflow/.local/lib/python3.7/site-packages/airflow/task/task_runner/standard_task_runner.py", line 85, in _start_by_fork
    args.func(args, dag=self.dag)
  File "/home/airflow/.local/lib/python3.7/site-packages/airflow/cli/cli_parser.py", line 48, in command
    return func(*args, **kwargs)
  File "/home/airflow/.local/lib/python3.7/site-packages/airflow/utils/cli.py", line 92, in wrapper
    return f(*args, **kwargs)
  File "/home/airflow/.local/lib/python3.7/site-packages/airflow/cli/commands/task_command.py", line 298, in task_run
    _run_task_by_selected_method(args, dag, ti)
  File "/home/airflow/.local/lib/python3.7/site-packages/airflow/cli/commands/task_command.py", line 107, in _run_task_by_selected_method
    _run_raw_task(args, ti)
  File "/home/airflow/.local/lib/python3.7/site-packages/airflow/cli/commands/task_command.py", line 184, in _run_raw_task
    error_file=args.error_file,
  File "/home/airflow/.local/lib/python3.7/site-packages/airflow/utils/session.py", line 70, in wrapper
    return func(*args, session=session, **kwargs)
  File "/home/airflow/.local/lib/python3.7/site-packages/airflow/models/taskinstance.py", line 1329, in _run_raw_task
    self._execute_task_with_callbacks(context)
  File "/home/airflow/.local/lib/python3.7/site-packages/airflow/models/taskinstance.py", line 1455, in _execute_task_with_callbacks
    result = self._execute_task(context, self.task)
  File "/home/airflow/.local/lib/python3.7/site-packages/airflow/models/taskinstance.py", line 1511, in _execute_task
    result = execute_callable(context=context)
  File "/home/airflow/.local/lib/python3.7/site-packages/airflow/operators/python.py", line 174, in execute
    return_value = self.execute_callable()
  File "/home/airflow/.local/lib/python3.7/site-packages/airflow/operators/python.py", line 185, in execute_callable
    return self.python_callable(*self.op_args, **self.op_kwargs)
  File "/opt/airflow/dags/dag_fligoo_etl.py", line 44, in wrapper
    to_execute = func(*args, **kwargs)
  File "/opt/airflow/dags/dag_fligoo_etl.py", line 140, in etl
    raw_df = transform(raw_df)
  File "/opt/airflow/dags/dag_fligoo_etl.py", line 44, in wrapper
    to_execute = func(*args, **kwargs)
  File "/opt/airflow/dags/dag_fligoo_etl.py", line 100, in transform
    'arrival.airport', 'arrival.timezone', 'arrival.terminal', 'airline.name', 'flight.number']]
  File "/home/airflow/.local/lib/python3.7/site-packages/pandas/core/frame.py", line 3464, in __getitem__
    indexer = self.loc._get_listlike_indexer(key, axis=1)[1]
  File "/home/airflow/.local/lib/python3.7/site-packages/pandas/core/indexing.py", line 1314, in _get_listlike_indexer
    self._validate_read_indexer(keyarr, indexer, axis)
  File "/home/airflow/.local/lib/python3.7/site-packages/pandas/core/indexing.py", line 1374, in _validate_read_indexer
    raise KeyError(f"None of [{key}] are in the [{axis_name}]")
KeyError: "None of [Index(['flight_date', 'flight_status', 'departure.airport',\n       'departure.timezone', 'arrival.airport', 'arrival.timezone',\n       'arrival.terminal', 'airline.name', 'flight.number'],\n      dtype='object')] are in the [columns]"
[2023-10-06 11:02:19,642] {local_task_job.py:154} INFO - Task exited with return code 1
[2023-10-06 11:02:19,721] {local_task_job.py:264} INFO - 0 downstream tasks scheduled from follow-on schedule check
